<mujoco model="opus">
  <compiler angle="radian" meshdir="meshes" eulerseq="zyx" autolimits="true"/>
  <default>
    <joint limited="true" damping=".53" armature="0.001" frictionloss="0.05"/>
    <geom condim="4" contype="1" conaffinity="15" friction="0.9 0.2 0.2" solref="0.001 2"/>
    <motor ctrllimited="true"/>
    <equality solref="0.001 2"/>
    <default class="visualgeom">
      <geom material="visualgeom" condim="1" contype="0" conaffinity="0"/>
    </default>
  </default>
  <option iterations="50" timestep="0.001" solver="PGS" gravity="0 0 -9.81"/>
  <asset>
    <mesh name="Torso" file="Torso.stl"/>
    <mesh name="shoulder_yaw_right" file="shoulder_yaw_right.stl"/>
    <mesh name="shoulder_yaw_left" file="shoulder_yaw_left.stl"/>
    <mesh name="right_shoulder_yaw_motor" file="right_shoulder_yaw_motor.stl"/>
    <mesh name="hip_yaw_right" file="hip_yaw_right.stl"/>
    <mesh name="hip_yaw_left" file="hip_yaw_left.stl"/>
    <mesh name="left_shoulder_yaw_motor" file="left_shoulder_yaw_motor.stl"/>
    <mesh name="hip_roll_right" file="hip_roll_right.stl"/>
    <mesh name="hip_roll_left" file="hip_roll_left.stl"/>
    <mesh name="Left_Hand" file="Left_Hand.stl"/>
    <mesh name="hand_right" file="hand_right.stl"/>
    <mesh name="knee_pitch_right" file="knee_pitch_right.stl"/>
    <mesh name="knee_pitch_right_2" file="knee_pitch_right_2.stl"/>
    <mesh name="ankle_pitch_right" file="ankle_pitch_right.stl"/>
    <mesh name="ankle_pitch_left" file="ankle_pitch_left.stl"/>
    <mesh name="foot_right" file="foot_right.stl"/>
    <mesh name="foot_left" file="foot_left.stl"/>
    <texture name="texplane" type="2d" builtin="checker" rgb1=".0 .0 .0" rgb2=".8 .8 .8" width="100" height="108"/>
    <material name="matplane" reflectance="0." texture="texplane" texrepeat="1 1" texuniform="true"/>
    <material name="visualgeom" rgba="0.5 0.9 0.2 1"/>
  </asset>
  <worldbody>
    <geom name="ground" type="plane" pos="0.001 0 0" quat="1 0 0 0" material="matplane" condim="1" conaffinity="15" size="0 0 1"/>
    <light directional="true" diffuse="0.6 0.6 0.6" specular="0.2 0.2 0.2" pos="0 0 4" dir="0 0 -1"/>
    <light directional="true" diffuse="0.4 0.4 0.4" specular="0.1 0.1 0.1" pos="0 0 5.0" dir="0 0 -1" castshadow="false"/>
    <body name="root" pos="0 0 0.31" quat="0 0 0 1">
      <freejoint name="root"/>
      <camera name="front" pos="0 -3 1" xyaxes="1 0 0 0 1 2" mode="trackcom"/>
      <camera name="side" pos="-2.893 -1.330 0.757" xyaxes="0.405 -0.914 0.000 0.419 0.186 0.889" mode="trackcom"/>
      <site name="imu" size="0.01" pos="0 0 0"/>
      <geom type="mesh" rgba="0.972549 0.529412 0.00392157 1" mesh="Torso" class="visualgeom"/>
      <geom type="mesh" rgba="0.972549 0.529412 0.00392157 1" mesh="Torso"/>
      <body name="shoulder_yaw_right" pos="-0.0781365 -0.000335556 0.0430533" quat="0.5 0.5 0.5 0.5">
        <inertial pos="-0.00037601 -0.00365665 -0.0174329" quat="0.647359 0.284476 0.647359 0.284476" mass="0.0403627" diaginertia="2.39887e-05 2.03034e-05 1.02268e-05"/>
        <joint name="right_shoulder_pitch" pos="0 0 0" axis="0 0 1" range="-1.5708 1.5708"/>
        <geom type="mesh" rgba="0.972549 0.529412 0.00392157 1" mesh="shoulder_yaw_right" class="visualgeom"/>
        <geom type="mesh" rgba="0.972549 0.529412 0.00392157 1" mesh="shoulder_yaw_right"/>
        <body name="right_shoulder_yaw_motor" pos="-0.018825 -0.0162992 -0.03" quat="-1.64085e-08 0.707107 1.64085e-08 0.707107">
          <inertial pos="-0.0149548 0.0320706 0.0181015" quat="0.688803 0.691851 0.153461 0.152782" mass="0.17146" diaginertia="0.000152631 0.000138758 4.07147e-05"/>
          <joint name="right_shoulder_yaw" pos="0 0 0" axis="0 0 -1" range="-1.5708 1.5708"/>
          <geom type="mesh" rgba="0.4 0.4 0.4 1" mesh="right_shoulder_yaw_motor" class="visualgeom"/>
          <geom type="mesh" rgba="0.4 0.4 0.4 1" mesh="right_shoulder_yaw_motor"/>
          <body name="Left_Hand" pos="-0.0300031 0.0643419 0.000250001" quat="0.976296 4.53101e-08 0 0.21644">
            <inertial pos="0.0011185 0.0461324 0.0182544" quat="0.706815 0.706815 -0.0202995 -0.0202995" mass="0.0751849" diaginertia="5.67243e-05 4.71032e-05 1.47264e-05"/>
            <joint name="right_elbow_yaw" pos="0 0 0" axis="0 0 1" range="-1.22173 1.22173"/>
            <geom type="mesh" rgba="0.972549 0.529412 0.00392157 1" mesh="Left_Hand" class="visualgeom"/>
            <geom type="mesh" rgba="0.972549 0.529412 0.00392157 1" mesh="Left_Hand"/>
          </body>
        </body>
      </body>
      <body name="shoulder_yaw_left" pos="0.0781635 -0.000335556 0.0430533" quat="0.5 -0.5 -0.5 0.5">
        <inertial pos="-0.000375909 0.00365652 -0.0174327" quat="0.284475 0.647359 0.284475 0.647359" mass="0.0403631" diaginertia="2.39889e-05 2.03034e-05 1.0227e-05"/>
        <joint name="left_shoulder_pitch" pos="0 0 0" axis="0 0 1" range="-1.5708 1.5708"/>
        <geom type="mesh" rgba="0.972549 0.529412 0.00392157 1" mesh="shoulder_yaw_left" class="visualgeom"/>
        <geom type="mesh" rgba="0.972549 0.529412 0.00392157 1" mesh="shoulder_yaw_left"/>
        <body name="left_shoulder_yaw_motor" pos="-0.018825 0.0162992 -0.03" quat="-1.64085e-08 0.707107 -1.64085e-08 -0.707107">
          <inertial pos="0.0149548 -0.0320706 -0.0181015" quat="0.689017 0.692092 0.152399 0.151787" mass="0.17146" diaginertia="0.000152247 0.000138758 4.10983e-05"/>
          <joint name="left_shoulder_yaw" pos="0 0 0" axis="0 0 1" range="-1.5708 1.5708"/>
          <geom type="mesh" rgba="0.4 0.4 0.4 1" mesh="left_shoulder_yaw_motor" class="visualgeom"/>
          <geom type="mesh" rgba="0.4 0.4 0.4 1" mesh="left_shoulder_yaw_motor"/>
          <body name="hand_right" pos="0.0300031 -0.0643419 -0.000250001" quat="2.26551e-08 -0.976296 -0.21644 5.0225e-09">
            <inertial pos="-0.00111857 0.0461326 0.0182546" quat="0.706815 0.706815 0.0202982 0.0202982" mass="0.0751837" diaginertia="5.67234e-05 4.71029e-05 1.47257e-05"/>
            <joint name="left_elbow_yaw" pos="0 0 0" axis="0 0 1" range="-1.22173 1.22173"/>
            <geom type="mesh" rgba="0.972549 0.529412 0.00392157 1" mesh="hand_right" class="visualgeom"/>
            <geom type="mesh" rgba="0.972549 0.529412 0.00392157 1" mesh="hand_right"/>
          </body>
        </body>
      </body>
      <body name="hip_yaw_right" pos="-0.0456365 -0.000335555 -0.0969467" quat="0.5 -0.5 -0.5 0.5">
        <inertial pos="-0.00777521 -0.0101889 0.0152725" quat="0.889874 0.455956 0.00767715 -0.0129746" mass="0.103196" diaginertia="4.3188e-05 4.07436e-05 3.38931e-05"/>
        <joint name="right_hip_pitch" pos="0 0 0" axis="0 0 -1" range="-1.5708 1.5708"/>
        <geom type="mesh" rgba="0.972549 0.529412 0.00392157 1" mesh="hip_yaw_right" class="visualgeom"/>
        <geom type="mesh" rgba="0.972549 0.529412 0.00392157 1" mesh="hip_yaw_right"/>
        <body name="hip_roll_right" pos="-0.0255 0.0025 0.01936" quat="0.707107 3.2817e-08 0.707107 -3.2817e-08">
          <inertial pos="5.22112e-05 0.0427183 0.0279625" quat="0.585477 0.810687 0.0016716 0.000214999" mass="0.111293" diaginertia="6.5719e-05 4.6539e-05 3.49745e-05"/>
          <joint name="right_hip_yaw" pos="0 0 0" axis="0 0 1" range="-0.0872665 1.5708"/>
          <geom type="mesh" rgba="0.972549 0.529412 0.00392157 1" mesh="hip_roll_right" class="visualgeom"/>
          <geom type="mesh" rgba="0.972549 0.529412 0.00392157 1" mesh="hip_roll_right"/>
          <body name="knee_pitch_right" pos="0 0.06776 0.015" quat="0.707107 0.707107 0 0">
            <inertial pos="0.000718952 -0.00237466 -0.0219131" quat="0.702278 0.0508037 -0.0647173 0.707132" mass="0.110612" diaginertia="6.96382e-05 6.25773e-05 2.61051e-05"/>
            <joint name="right_hip_roll" pos="0 0 0" axis="0 0 1" range="-0.785398 0.785398"/>
            <geom type="mesh" rgba="0.972549 0.529412 0.00392157 1" mesh="knee_pitch_right" class="visualgeom"/>
            <geom type="mesh" rgba="0.972549 0.529412 0.00392157 1" mesh="knee_pitch_right"/>
            <body name="ankle_pitch_right" pos="0.018825 -9.39161e-10 -0.04221" quat="0.5 -0.5 -0.5 0.5">
              <inertial pos="-5.29027e-07 0.0409224 0.0178642" quat="0.709959 0.704243 3.3304e-05 3.30359e-05" mass="0.109625" diaginertia="5.75137e-05 4.60143e-05 2.78632e-05"/>
              <joint name="right_knee_pitch" pos="0 0 0" axis="0 0 1" range="-1.0472 1.0472"/>
              <geom type="mesh" rgba="0.972549 0.529412 0.00392157 1" mesh="ankle_pitch_right" class="visualgeom"/>
              <geom type="mesh" rgba="0.972549 0.529412 0.00392157 1" mesh="ankle_pitch_right"/>
              <body name="foot_right" pos="0 0.06022 -1.3e-08" quat="2.32051e-08 -1 0 0">
                <inertial pos="-0.00778227 -0.0161914 -0.0178319" quat="0.488777 0.488777 0.510977 0.510977" mass="0.0406222" diaginertia="3.78658e-05 2.8894e-05 1.35969e-05"/>
                <joint name="right_ankle_pitch" pos="0 0 0" axis="0 0 -1" range="-1.0472 1.0472"/>
                <geom type="mesh" rgba="0.972549 0.529412 0.00392157 1" mesh="foot_right" class="visualgeom"/>
                <geom type="mesh" rgba="0.972549 0.529412 0.00392157 1" mesh="foot_right"/>
              </body>
            </body>
          </body>
        </body>
      </body>
      <body name="hip_yaw_left" pos="0.0456635 -0.000335555 -0.0969467" quat="0.5 0.5 0.5 0.5">
        <inertial pos="-0.00777616 0.0101887 0.0152718" quat="0.45592 0.889889 0.0131744 -0.00779523" mass="0.103202" diaginertia="4.31891e-05 4.07457e-05 3.38951e-05"/>
        <joint name="left_hip_pitch" pos="0 0 0" axis="0 0 -1" range="-1.5708 1.5708"/>
        <geom type="mesh" rgba="0.972549 0.529412 0.00392157 1" mesh="hip_yaw_left" class="visualgeom"/>
        <geom type="mesh" rgba="0.972549 0.529412 0.00392157 1" mesh="hip_yaw_left"/>
        <body name="hip_roll_left" pos="-0.0255 -0.0025 0.01936" quat="1.64085e-08 -0.707107 -1.64085e-08 -0.707107">
          <inertial pos="-5.22128e-05 0.0427184 0.0279626" quat="0.585474 0.810689 -0.00167161 -0.000214986" mass="0.111294" diaginertia="6.57191e-05 4.65391e-05 3.49746e-05"/>
          <joint name="left_hip_yaw" pos="0 0 0" axis="0 0 1" range="-1.5708 0.0872665"/>
          <geom type="mesh" rgba="0.972549 0.529412 0.00392157 1" mesh="hip_roll_left" class="visualgeom"/>
          <geom type="mesh" rgba="0.972549 0.529412 0.00392157 1" mesh="hip_roll_left"/>
          <body name="knee_pitch_right_2" pos="0 0.06776 0.015" quat="0.707107 0.707107 0 0">
            <inertial pos="-0.000643821 -0.00237466 -0.0244388" quat="0.706931 0.0631453 -0.0485932 0.70278" mass="0.110612" diaginertia="7.52582e-05 6.81301e-05 2.60379e-05"/>
            <joint name="left_hip_roll" pos="0 0 0" axis="0 0 1" range="-0.785398 0.785398"/>
            <geom type="mesh" rgba="0.972549 0.529412 0.00392157 1" mesh="knee_pitch_right_2" class="visualgeom"/>
            <geom type="mesh" rgba="0.972549 0.529412 0.00392157 1" mesh="knee_pitch_right_2"/>
            <body name="ankle_pitch_left" pos="-0.018775 9.39161e-10 -0.04596" quat="0.5 -0.5 -0.5 0.5">
              <inertial pos="2.15197e-06 0.0383739 -0.019579" quat="0.737365 0.675494 4.40773e-06 4.03788e-06" mass="0.109625" diaginertia="5.33242e-05 4.18066e-05 2.78814e-05"/>
              <joint name="left_knee_pitch" pos="0 0 0" axis="0 0 -1" range="-1.0472 1.0472"/>
              <geom type="mesh" rgba="0.972549 0.529412 0.00392157 1" mesh="ankle_pitch_left" class="visualgeom"/>
              <geom type="mesh" rgba="0.972549 0.529412 0.00392157 1" mesh="ankle_pitch_left"/>
              <body name="foot_left" pos="1.3459e-09 0.05647 -0.000450004" quat="2.32051e-08 -1 4.64102e-08 0">
                <inertial pos="-0.00778227 -0.0161914 0.0178319" quat="0.488777 0.488777 0.510977 0.510977" mass="0.0406222" diaginertia="3.78658e-05 2.8894e-05 1.35969e-05"/>
                <joint name="left_ankle_pitch" pos="0 0 0" axis="0 0 1" range="-1.0472 1.0472"/>
                <geom type="mesh" rgba="0.972549 0.529412 0.00392157 1" mesh="foot_left" class="visualgeom"/>
                <geom type="mesh" rgba="0.972549 0.529412 0.00392157 1" mesh="foot_left"/>
              </body>
            </body>
          </body>
        </body>
      </body>
    </body>
  </worldbody>

  <actuator>
    <motor name="left_hip_pitch" joint="left_hip_pitch" ctrllimited="true" ctrlrange="-20 20" gear="1" />
    <motor name="left_hip_yaw" joint="left_hip_yaw" ctrllimited="true" ctrlrange="-20 20" gear="1" />
    <motor name="left_hip_roll" joint="left_hip_roll" ctrllimited="true" ctrlrange="-20 20" gear="1" />
    <motor name="left_knee_pitch" joint="left_knee_pitch" ctrllimited="true" ctrlrange="-20 20" gear="1" />
    <motor name="left_ankle_pitch" joint="left_ankle_pitch" ctrllimited="true" ctrlrange="-20 20" gear="1" />
    <motor name="left_shoulder_pitch" joint="left_shoulder_pitch" ctrllimited="true" ctrlrange="-20 20" gear="1" />
    <motor name="left_shoulder_yaw" joint="left_shoulder_yaw" ctrllimited="true" ctrlrange="-20 20" gear="1" />
    <motor name="left_elbow_yaw" joint="left_elbow_yaw" ctrllimited="true" ctrlrange="-20 20" gear="1" />

    <motor name="right_shoulder_pitch" joint="right_shoulder_pitch" ctrllimited="true" ctrlrange="-20 20" gear="1" />
    <motor name="right_shoulder_yaw" joint="right_shoulder_yaw" ctrllimited="true" ctrlrange="-20 20" gear="1" />
    <motor name="right_elbow_yaw" joint="right_elbow_yaw" ctrllimited="true" ctrlrange="-20 20" gear="1" />
    <motor name="right_hip_pitch" joint="right_hip_pitch" ctrllimited="true" ctrlrange="-20 20" gear="1" />
    <motor name="right_hip_yaw" joint="right_hip_yaw" ctrllimited="true" ctrlrange="-20 20" gear="1" />
    <motor name="right_hip_roll" joint="right_hip_roll" ctrllimited="true" ctrlrange="-20 20" gear="1" />
    <motor name="right_knee_pitch" joint="right_knee_pitch" ctrllimited="true" ctrlrange="-20 20" gear="1" />
    <motor name="right_ankle_pitch" joint="right_ankle_pitch" ctrllimited="true" ctrlrange="-20 20" gear="1" />
  </actuator>
  <sensor>
    <framequat name="orientation" objtype="site" noise="0.001" objname="imu"/>
    <gyro name="angular-velocity" site="imu" noise="0.005" cutoff="34.9"/>
  </sensor>
</mujoco>